<?xml version='1.0' encoding='ASCII'?>
<robot name="inspire_hand_right">
  <link name="dummy_x_translation_link">
    <inertial>
      <origin xyz="0.0 0.0 0.0" rpy="0.0 0.0 0.0"/>
      <mass value="0.01"/>
      <inertia ixx="0.0001" ixy="0.0" ixz="0.0" iyy="0.0001" iyz="0.0" izz="0.0001"/>
    </inertial>
  </link>
  <link name="dummy_y_translation_link">
    <inertial>
      <origin xyz="0.0 0.0 0.0" rpy="0.0 0.0 0.0"/>
      <mass value="0.01"/>
      <inertia ixx="0.0001" ixy="0.0" ixz="0.0" iyy="0.0001" iyz="0.0" izz="0.0001"/>
    </inertial>
  </link>
  <link name="dummy_z_translation_link">
    <inertial>
      <origin xyz="0.0 0.0 0.0" rpy="0.0 0.0 0.0"/>
      <mass value="0.01"/>
      <inertia ixx="0.0001" ixy="0.0" ixz="0.0" iyy="0.0001" iyz="0.0" izz="0.0001"/>
    </inertial>
  </link>
  <link name="dummy_x_rotation_link">
    <inertial>
      <origin xyz="0.0 0.0 0.0" rpy="0.0 0.0 0.0"/>
      <mass value="0.01"/>
      <inertia ixx="0.0001" ixy="0.0" ixz="0.0" iyy="0.0001" iyz="0.0" izz="0.0001"/>
    </inertial>
  </link>
  <link name="dummy_y_rotation_link">
    <inertial>
      <origin xyz="0.0 0.0 0.0" rpy="0.0 0.0 0.0"/>
      <mass value="0.01"/>
      <inertia ixx="0.0001" ixy="0.0" ixz="0.0" iyy="0.0001" iyz="0.0" izz="0.0001"/>
    </inertial>
  </link>
  <link name="dummy_z_rotation_link">
    <inertial>
      <origin xyz="0.0 0.0 0.0" rpy="0.0 0.0 0.0"/>
      <mass value="0.01"/>
      <inertia ixx="0.0001" ixy="0.0" ixz="0.0" iyy="0.0001" iyz="0.0" izz="0.0001"/>
    </inertial>
  </link>
  <link name="base"/>
  <link name="hand_base_link">
    <inertial>
      <origin xyz="-0.0025264 -0.066047 0.0019598" rpy="0.0 0.0 0.0"/>
      <mass value="0.14143"/>
      <inertia ixx="0.00012281" ixy="2.1711e-06" ixz="1.7709e-06" iyy="8.3832e-05" iyz="-1.6551e-06" izz="7.6663e-05"/>
    </inertial>
    <visual>
      <geometry>
        <mesh filename="/home/wangminqi/workspace/test/packages/hands/inspire_hand/meshes/visual/right_base_link.glb"/>
      </geometry>
      <origin xyz="0.0 0.0 0.0" rpy="0.0 0.0 0.0"/>
    </visual>
    <collision>
      <geometry>
        <cylinder radius="0.028" length="0.0278"/>
      </geometry>
      <origin xyz="0.0 -0.0136 0.0" rpy="1.57079 0.0 -6.123233995614214e-17"/>
    </collision>
    <collision>
      <geometry>
        <box size="0.0391 0.0202 0.0574"/>
      </geometry>
      <origin xyz="-0.0032 -0.038 0.0" rpy="0.0 0.0 0.0"/>
    </collision>
    <collision>
      <geometry>
        <box size="0.0391 0.04 0.0814"/>
      </geometry>
      <origin xyz="-0.0032 -0.0682 0.0" rpy="0.0 0.0 0.0"/>
    </collision>
    <collision>
      <geometry>
        <box size="0.0322 0.04 0.0814"/>
      </geometry>
      <origin xyz="0.0 -0.1081 0.0" rpy="0.0 0.0 0.0"/>
    </collision>
    <collision>
      <geometry>
        <box size="0.0125 0.0111 0.0089"/>
      </geometry>
      <origin xyz="-0.0016 -0.134 0.0309" rpy="0.0 0.0 0.0"/>
    </collision>
    <collision>
      <geometry>
        <box size="0.0125 0.0111 0.0089"/>
      </geometry>
      <origin xyz="-0.0016 -0.134 0.0118" rpy="0.0 0.0 0.0"/>
    </collision>
    <collision>
      <geometry>
        <box size="0.0125 0.0111 0.0089"/>
      </geometry>
      <origin xyz="-0.0016 -0.134 -0.007" rpy="0.0 0.0 0.0"/>
    </collision>
    <collision>
      <geometry>
        <box size="0.0125 0.0111 0.0089"/>
      </geometry>
      <origin xyz="-0.0016 -0.134 -0.0262" rpy="0.0 0.0 0.0"/>
    </collision>
  </link>
  <link name="thumb_proximal_base">
    <inertial>
      <origin xyz="-0.0048064 0.0009382 -0.00757" rpy="0.0 0.0 0.0"/>
      <mass value="0.0018869"/>
      <inertia ixx="5.816e-08" ixy="1.4539e-08" ixz="4.491e-09" iyy="7.9161e-08" iyz="-1.8727e-09" izz="6.7433e-08"/>
    </inertial>
    <visual>
      <geometry>
        <mesh filename="/home/wangminqi/workspace/test/packages/hands/inspire_hand/meshes/visual/right_thumb_proximal_base.glb"/>
      </geometry>
      <origin xyz="0.0 0.0 0.0" rpy="0.0 0.0 0.0"/>
    </visual>
    <collision>
      <geometry>
        <mesh filename="/home/wangminqi/workspace/test/packages/hands/inspire_hand/meshes/collision/right_thumb_proximal_base.obj"/>
      </geometry>
      <origin xyz="0.0 0.0 0.0" rpy="0.0 0.0 0.0"/>
    </collision>
  </link>
  <link name="thumb_proximal">
    <inertial>
      <origin xyz="0.021932 0.012785 -0.0080386" rpy="0.0 0.0 0.0"/>
      <mass value="0.0066075"/>
      <inertia ixx="1.5686e-06" ixy="-7.8296e-07" ixz="8.9143e-10" iyy="1.7353e-06" iyz="-1.0191e-09" izz="2.786e-06"/>
    </inertial>
    <visual>
      <geometry>
        <mesh filename="/home/wangminqi/workspace/test/packages/hands/inspire_hand/meshes/visual/right_thumb_proximal.glb"/>
      </geometry>
      <origin xyz="0.0 0.0 0.0" rpy="0.0 0.0 0.0"/>
    </visual>
    <collision>
      <geometry>
        <mesh filename="/home/wangminqi/workspace/test/packages/hands/inspire_hand/meshes/collision/right_thumb_proximal.obj"/>
      </geometry>
      <origin xyz="0.0 0.0 0.0" rpy="0.0 0.0 0.0"/>
    </collision>
  </link>
  <link name="thumb_intermediate">
    <inertial>
      <origin xyz="0.0095544 -0.0016282 -0.0071997" rpy="0.0 0.0 0.0"/>
      <mass value="0.0037847"/>
      <inertia ixx="3.6981e-07" ixy="-9.8581e-08" ixz="-4.7469e-12" iyy="3.2394e-07" iyz="1.0939e-12" izz="4.6531e-07"/>
    </inertial>
    <visual>
      <geometry>
        <mesh filename="/home/wangminqi/workspace/test/packages/hands/inspire_hand/meshes/visual/right_thumb_intermediate.glb"/>
      </geometry>
      <origin xyz="0.0 0.0 0.0" rpy="0.0 0.0 0.0"/>
    </visual>
    <collision>
      <geometry>
        <mesh filename="/home/wangminqi/workspace/test/packages/hands/inspire_hand/meshes/collision/right_thumb_intermediate.obj"/>
      </geometry>
      <origin xyz="0.0 0.0 0.0" rpy="0.0 0.0 0.0"/>
    </collision>
  </link>
  <link name="thumb_distal">
    <inertial>
      <origin xyz="0.0092888 0.0049529 -0.0060033" rpy="0.0 0.0 0.0"/>
      <mass value="0.0033441"/>
      <inertia ixx="1.3632e-07" ixy="-5.6788e-08" ixz="-9.2764e-11" iyy="1.4052e-07" iyz="-1.2283e-10" izz="2.0026e-07"/>
    </inertial>
    <visual>
      <geometry>
        <mesh filename="/home/wangminqi/workspace/test/packages/hands/inspire_hand/meshes/visual/right_thumb_distal.glb"/>
      </geometry>
      <origin xyz="0.0 0.0 0.0" rpy="0.0 0.0 0.0"/>
    </visual>
    <collision>
      <geometry>
        <mesh filename="/home/wangminqi/workspace/test/packages/hands/inspire_hand/meshes/collision/right_thumb_distal.obj"/>
      </geometry>
      <origin xyz="0.0 0.0 0.0" rpy="0.0 0.0 0.0"/>
    </collision>
  </link>
  <link name="index_proximal">
    <inertial>
      <origin xyz="0.0012259 0.011942 -0.0060001" rpy="0.0 0.0 0.0"/>
      <mass value="0.0042403"/>
      <inertia ixx="6.6232e-07" ixy="-1.5775e-08" ixz="1.8515e-12" iyy="2.1146e-07" iyz="-5.0828e-12" izz="6.9398e-07"/>
    </inertial>
    <visual>
      <geometry>
        <mesh filename="/home/wangminqi/workspace/test/packages/hands/inspire_hand/meshes/visual/right_index_proximal.glb"/>
      </geometry>
      <origin xyz="0.0 0.0 0.0" rpy="0.0 0.0 0.0"/>
    </visual>
    <collision>
      <geometry>
        <mesh filename="/home/wangminqi/workspace/test/packages/hands/inspire_hand/meshes/collision/right_index_proximal.obj"/>
      </geometry>
      <origin xyz="0.0 0.0 0.0" rpy="0.0 0.0 0.0"/>
    </collision>
  </link>
  <link name="index_intermediate">
    <inertial>
      <origin xyz="0.0019697 0.019589 -0.005" rpy="0.0 0.0 0.0"/>
      <mass value="0.0045683"/>
      <inertia ixx="7.6111e-07" ixy="8.7637e-08" ixz="-3.7751e-13" iyy="9.6076e-08" iyz="9.9444e-13" izz="7.8179e-07"/>
    </inertial>
    <visual>
      <geometry>
        <mesh filename="/home/wangminqi/workspace/test/packages/hands/inspire_hand/meshes/visual/right_index_intermediate.glb"/>
      </geometry>
      <origin xyz="0.0 0.0 0.0" rpy="0.0 0.0 0.0"/>
    </visual>
    <collision>
      <geometry>
        <mesh filename="/home/wangminqi/workspace/test/packages/hands/inspire_hand/meshes/collision/right_index_intermediate.obj"/>
      </geometry>
      <origin xyz="0.0 0.0 0.0" rpy="0.0 0.0 0.0"/>
    </collision>
  </link>
  <link name="middle_proximal">
    <inertial>
      <origin xyz="0.001297 0.011934 -0.0060001" rpy="0.0 0.0 0.0"/>
      <mass value="0.0042403"/>
      <inertia ixx="6.6211e-07" ixy="-1.8461e-08" ixz="1.8002e-12" iyy="2.1167e-07" iyz="-6.6808e-12" izz="6.9397e-07"/>
    </inertial>
    <visual>
      <geometry>
        <mesh filename="/home/wangminqi/workspace/test/packages/hands/inspire_hand/meshes/visual/right_index_proximal.glb"/>
      </geometry>
      <origin xyz="0.0 0.0 0.0" rpy="0.0 0.0 0.0"/>
    </visual>
    <collision>
      <geometry>
        <mesh filename="/home/wangminqi/workspace/test/packages/hands/inspire_hand/meshes/collision/right_index_proximal.obj"/>
      </geometry>
      <origin xyz="0.0 0.0 0.0" rpy="0.0 0.0 0.0"/>
    </collision>
  </link>
  <link name="middle_intermediate">
    <inertial>
      <origin xyz="0.001921 0.020796 -0.005" rpy="0.0 0.0 0.0"/>
      <mass value="0.0050396"/>
      <inertia ixx="9.5822e-07" ixy="1.1425e-07" ixz="-2.4791e-12" iyy="1.0646e-07" iyz="5.9173e-12" izz="9.8384e-07"/>
    </inertial>
    <visual>
      <geometry>
        <mesh filename="/home/wangminqi/workspace/test/packages/hands/inspire_hand/meshes/visual/right_middle_intermediate.glb"/>
      </geometry>
      <origin xyz="0.0 0.0 0.0" rpy="0.0 0.0 0.0"/>
    </visual>
    <collision>
      <geometry>
        <mesh filename="/home/wangminqi/workspace/test/packages/hands/inspire_hand/meshes/collision/right_middle_intermediate.obj"/>
      </geometry>
      <origin xyz="0.0 0.0 0.0" rpy="0.0 0.0 0.0"/>
    </collision>
  </link>
  <link name="ring_proximal">
    <inertial>
      <origin xyz="0.001297 0.011934 -0.0060002" rpy="0.0 0.0 0.0"/>
      <mass value="0.0042403"/>
      <inertia ixx="6.6211e-07" ixy="-1.8461e-08" ixz="1.5793e-12" iyy="2.1167e-07" iyz="-6.6868e-12" izz="6.9397e-07"/>
    </inertial>
    <visual>
      <geometry>
        <mesh filename="/home/wangminqi/workspace/test/packages/hands/inspire_hand/meshes/visual/right_index_proximal.glb"/>
      </geometry>
      <origin xyz="0.0 0.0 0.0" rpy="0.0 0.0 0.0"/>
    </visual>
    <collision>
      <geometry>
        <mesh filename="/home/wangminqi/workspace/test/packages/hands/inspire_hand/meshes/collision/right_index_proximal.obj"/>
      </geometry>
      <origin xyz="0.0 0.0 0.0" rpy="0.0 0.0 0.0"/>
    </collision>
  </link>
  <link name="ring_intermediate">
    <inertial>
      <origin xyz="0.0021753 0.019567 -0.005" rpy="0.0 0.0 0.0"/>
      <mass value="0.0045683"/>
      <inertia ixx="7.6286e-07" ixy="8.0635e-08" ixz="-6.1562e-13" iyy="9.431e-08" iyz="5.8619e-13" izz="7.8177e-07"/>
    </inertial>
    <visual>
      <geometry>
        <mesh filename="/home/wangminqi/workspace/test/packages/hands/inspire_hand/meshes/visual/right_index_intermediate.glb"/>
      </geometry>
      <origin xyz="0.0 0.0 0.0" rpy="0.0 0.0 0.0"/>
    </visual>
    <collision>
      <geometry>
        <mesh filename="/home/wangminqi/workspace/test/packages/hands/inspire_hand/meshes/collision/right_index_intermediate.obj"/>
      </geometry>
      <origin xyz="0.0 0.0 0.0" rpy="0.0 0.0 0.0"/>
    </collision>
  </link>
  <link name="pinky_proximal">
    <inertial>
      <origin xyz="0.001297 0.011934 -0.0060001" rpy="0.0 0.0 0.0"/>
      <mass value="0.0042403"/>
      <inertia ixx="6.6211e-07" ixy="-1.8461e-08" ixz="1.6907e-12" iyy="2.1167e-07" iyz="-6.9334e-12" izz="6.9397e-07"/>
    </inertial>
    <visual>
      <geometry>
        <mesh filename="/home/wangminqi/workspace/test/packages/hands/inspire_hand/meshes/visual/right_index_proximal.glb"/>
      </geometry>
      <origin xyz="0.0 0.0 0.0" rpy="0.0 0.0 0.0"/>
    </visual>
    <collision>
      <geometry>
        <mesh filename="/home/wangminqi/workspace/test/packages/hands/inspire_hand/meshes/collision/right_index_proximal.obj"/>
      </geometry>
      <origin xyz="0.0 0.0 0.0" rpy="0.0 0.0 0.0"/>
    </collision>
  </link>
  <link name="pinky_intermediate">
    <inertial>
      <origin xyz="0.0024748 0.016203 -0.0050031" rpy="0.0 0.0 0.0"/>
      <mass value="0.0035996"/>
      <inertia ixx="4.3913e-07" ixy="4.1418e-08" ixz="3.7168e-11" iyy="7.0247e-08" iyz="5.8613e-11" izz="4.4867e-07"/>
    </inertial>
    <visual>
      <geometry>
        <mesh filename="/home/wangminqi/workspace/test/packages/hands/inspire_hand/meshes/visual/right_pinky_intermediate.glb"/>
      </geometry>
      <origin xyz="0.0 0.0 0.0" rpy="0.0 0.0 0.0"/>
    </visual>
    <collision>
      <geometry>
        <mesh filename="/home/wangminqi/workspace/test/packages/hands/inspire_hand/meshes/collision/right_pinky_intermediate.obj"/>
      </geometry>
      <origin xyz="0.0 0.0 0.0" rpy="0.0 0.0 0.0"/>
    </collision>
  </link>
  <link name="thumb_tip"/>
  <link name="index_tip"/>
  <link name="middle_tip"/>
  <link name="ring_tip"/>
  <link name="pinky_tip"/>
  <joint name="dummy_x_translation_joint" type="prismatic">
    <parent link="dummy_x_translation_link"/>
    <child link="dummy_y_translation_link"/>
    <origin xyz="0.0 0.0 0.0" rpy="0.0 0.0 0.0"/>
    <axis xyz="1 0 0"/>
    <limit effort="10" velocity="3.14" lower="-5" upper="5"/>
  </joint>
  <joint name="dummy_y_translation_joint" type="prismatic">
    <parent link="dummy_y_translation_link"/>
    <child link="dummy_z_translation_link"/>
    <origin xyz="0.0 0.0 0.0" rpy="0.0 0.0 0.0"/>
    <axis xyz="0 1 0"/>
    <limit effort="10" velocity="3.14" lower="-5" upper="5"/>
  </joint>
  <joint name="dummy_z_translation_joint" type="prismatic">
    <parent link="dummy_z_translation_link"/>
    <child link="dummy_x_rotation_link"/>
    <origin xyz="0.0 0.0 0.0" rpy="0.0 0.0 0.0"/>
    <axis xyz="0 0 1"/>
    <limit effort="10" velocity="3.14" lower="-5" upper="5"/>
  </joint>
  <joint name="dummy_x_rotation_joint" type="revolute">
    <parent link="dummy_x_rotation_link"/>
    <child link="dummy_y_rotation_link"/>
    <origin xyz="0.0 0.0 0.0" rpy="0.0 0.0 0.0"/>
    <axis xyz="1 0 0"/>
    <limit effort="10" velocity="3.14" lower="-6.283185307179586" upper="6.283185307179586"/>
  </joint>
  <joint name="dummy_y_rotation_joint" type="revolute">
    <parent link="dummy_y_rotation_link"/>
    <child link="dummy_z_rotation_link"/>
    <origin xyz="0.0 0.0 0.0" rpy="0.0 0.0 0.0"/>
    <axis xyz="0 1 0"/>
    <limit effort="10" velocity="3.14" lower="-6.283185307179586" upper="6.283185307179586"/>
  </joint>
  <joint name="dummy_z_rotation_joint" type="revolute">
    <parent link="dummy_z_rotation_link"/>
    <child link="base"/>
    <origin xyz="0.0 0.0 0.0" rpy="0.0 0.0 0.0"/>
    <axis xyz="0 0 1"/>
    <limit effort="10" velocity="3.14" lower="-6.283185307179586" upper="6.283185307179586"/>
  </joint>
  <joint name="base_joint" type="fixed">
    <parent link="base"/>
    <child link="hand_base_link"/>
    <origin xyz="0.0 0.0 0.0" rpy="-1.57079 0.0 3.14159"/>
    <axis xyz="1.0 0.0 0.0"/>
  </joint>
  <joint name="thumb_proximal_yaw_joint" type="revolute">
    <parent link="hand_base_link"/>
    <child link="thumb_proximal_base"/>
    <origin xyz="-0.01696 -0.0691 -0.02045" rpy="-1.5707926536064634 -1.5707926535755432 -3.1415926535731233"/>
    <axis xyz="0.0 0.0 -1.0"/>
    <limit effort="1.0" velocity="0.5" lower="0.0" upper="1.308"/>
  </joint>
  <joint name="thumb_proximal_pitch_joint" type="revolute">
    <parent link="thumb_proximal_base"/>
    <child link="thumb_proximal"/>
    <origin xyz="-0.0088099 0.010892 -0.00925" rpy="1.5708 0.0 2.8587"/>
    <axis xyz="0.0 0.0 1.0"/>
    <limit effort="1.0" velocity="0.5" lower="0.0" upper="0.6"/>
  </joint>
  <joint name="thumb_intermediate_joint" type="revolute">
    <parent link="thumb_proximal"/>
    <child link="thumb_intermediate"/>
    <origin xyz="0.04407 0.034553 -0.0008" rpy="0.0 0.0 0.0"/>
    <axis xyz="0.0 0.0 1.0"/>
    <limit effort="1.0" velocity="0.5" lower="0.0" upper="0.8"/>
  </joint>
  <joint name="thumb_distal_joint" type="revolute">
    <parent link="thumb_intermediate"/>
    <child link="thumb_distal"/>
    <origin xyz="0.020248 0.010156 -0.0012" rpy="0.0 0.0 0.0"/>
    <axis xyz="0.0 0.0 1.0"/>
    <limit effort="1.0" velocity="0.5" lower="0.0" upper="0.4"/>
  </joint>
  <joint name="index_proximal_joint" type="revolute">
    <parent link="hand_base_link"/>
    <child link="index_proximal"/>
    <origin xyz="0.00028533 -0.13653 -0.032268" rpy="-3.1067 2.220446049250313e-16 2.1361253105912372e-18"/>
    <axis xyz="0.0 0.0 1.0"/>
    <limit effort="1.0" velocity="0.5" lower="0.0" upper="1.47"/>
  </joint>
  <joint name="index_intermediate_joint" type="revolute">
    <parent link="index_proximal"/>
    <child link="index_intermediate"/>
    <origin xyz="-0.0026138 0.032026 -0.001" rpy="0.0 0.0 0.0"/>
    <axis xyz="0.0 0.0 1.0"/>
    <limit effort="1.0" velocity="0.5" lower="-0.04545" upper="1.56"/>
  </joint>
  <joint name="middle_proximal_joint" type="revolute">
    <parent link="hand_base_link"/>
    <child link="middle_proximal"/>
    <origin xyz="0.00028533 -0.1371 -0.01295" rpy="3.1415853071795867 2.220446049250313e-16 -4.498378872394757e-22"/>
    <axis xyz="0.0 0.0 1.0"/>
    <limit effort="1.0" velocity="0.5" lower="0.0" upper="1.47"/>
  </joint>
  <joint name="middle_intermediate_joint" type="revolute">
    <parent link="middle_proximal"/>
    <child link="middle_intermediate"/>
    <origin xyz="-0.0024229 0.032041 -0.001" rpy="0.0 0.0 0.0"/>
    <axis xyz="0.0 0.0 1.0"/>
    <limit effort="1.0" velocity="0.5" lower="-0.04545" upper="1.56"/>
  </joint>
  <joint name="ring_proximal_joint" type="revolute">
    <parent link="hand_base_link"/>
    <child link="ring_proximal"/>
    <origin xyz="0.00028533 -0.13691 0.0062872" rpy="3.0892 2.220446049250313e-16 -3.2066572654899916e-18"/>
    <axis xyz="0.0 0.0 1.0"/>
    <limit effort="1.0" velocity="0.5" lower="0.0" upper="1.47"/>
  </joint>
  <joint name="ring_intermediate_joint" type="revolute">
    <parent link="ring_proximal"/>
    <child link="ring_intermediate"/>
    <origin xyz="-0.0024229 0.032041 -0.001" rpy="0.0 0.0 0.0"/>
    <axis xyz="0.0 0.0 1.0"/>
    <limit effort="1.0" velocity="0.5" lower="-0.04545" upper="1.56"/>
  </joint>
  <joint name="pinky_proximal_joint" type="revolute">
    <parent link="hand_base_link"/>
    <child link="pinky_proximal"/>
    <origin xyz="0.00028533 -0.13571 0.025488" rpy="3.0369 2.220446049250313e-16 -6.398871996445996e-18"/>
    <axis xyz="0.0 0.0 1.0"/>
    <limit effort="1.0" velocity="0.5" lower="0.0" upper="1.47"/>
  </joint>
  <joint name="pinky_intermediate_joint" type="revolute">
    <parent link="pinky_proximal"/>
    <child link="pinky_intermediate"/>
    <origin xyz="-0.0024229 0.032041 -0.001" rpy="0.0 0.0 0.0"/>
    <axis xyz="0.0 0.0 1.0"/>
    <limit effort="1.0" velocity="0.5" lower="-0.04545" upper="1.56"/>
  </joint>
  <joint name="thumb_tip_joint" type="fixed">
    <parent link="thumb_distal"/>
    <child link="thumb_tip"/>
    <origin xyz="0.0202 0.014 -0.006" rpy="0.0 0.0 0.0"/>
    <axis xyz="1.0 0.0 0.0"/>
  </joint>
  <joint name="index_tip_joint" type="fixed">
    <parent link="index_intermediate"/>
    <child link="index_tip"/>
    <origin xyz="-0.0008 0.045 -0.005" rpy="0.0 0.0 0.0"/>
    <axis xyz="1.0 0.0 0.0"/>
  </joint>
  <joint name="middle_tip_joint" type="fixed">
    <parent link="middle_intermediate"/>
    <child link="middle_tip"/>
    <origin xyz="-0.001 0.048 -0.005" rpy="0.0 0.0 0.0"/>
    <axis xyz="1.0 0.0 0.0"/>
  </joint>
  <joint name="ring_tip_joint" type="fixed">
    <parent link="ring_intermediate"/>
    <child link="ring_tip"/>
    <origin xyz="-0.0008 0.045 -0.005" rpy="0.0 0.0 0.0"/>
    <axis xyz="1.0 0.0 0.0"/>
  </joint>
  <joint name="pinky_tip_joint" type="fixed">
    <parent link="pinky_intermediate"/>
    <child link="pinky_tip"/>
    <origin xyz="-0.0008 0.037 -0.005" rpy="0.0 0.0 0.0"/>
    <axis xyz="1.0 0.0 0.0"/>
  </joint>
</robot>
